error: expected argument name, found `)`

  --> mutant.rs:26:57

   |

26 | extern "rust-call" fn call ( # [ export_name = "2200" ] ) -> Self :: Output ;

   |                                                         ^ expected argument name



error: internal compiler error: compiler/rustc_typeck/src/check/callee.rs:236:29: input to call/call_mut is not a ref?

  --> mutant.rs:44:1

   |

44 | ( * a ) ( )

   | ^^^^^^^^^^^



thread 'rustc' panicked at 'Box<Any>', /rustc/07e0e2ec268c140e607e1ac7f49f145612d0f597/library/std/src/panic.rs:59:5

note: run with `RUST_BACKTRACE=1` environment variable to display a backtrace



note: the compiler unexpectedly panicked. this is a bug.



note: we would appreciate a bug report: https://github.com/rust-lang/rust/issues/new?labels=C-bug%2C+I-ICE%2C+T-compiler&template=ice.md



note: rustc 1.53.0-nightly (07e0e2ec2 2021-03-24) running on x86_64-unknown-linux-gnu



note: compiler flags: -Z mir-opt-level=3 -Z new-llvm-pass-manager=yes -Z unsound-mir-opts=yes -Z polonius=yes -Z polymorphize=yes -C debuginfo=2 -C opt-level=3 --crate-type staticlib



query stack during panic:

#0 [typeck] type-checking `call_through_fn_trait`

#1 [typeck_item_bodies] type-checking all item bodies

end of query stack

error: aborting due to 2 previous errors



